Workbook

Sheet Dashboard
B1: LOWCOUNTRY MOTION PHYSICAL THERAPY · NO-SHOW & SCHEDULING DASHBOARD | T1: All providers
B2: Fictional clinic · synthetic data · Oct 2025 to Sep 2026 · Built by The Charted Co | T2: Dr. Chen, DPT
T3: Dr. Okafor, DPT
B4: Show provider: | C4: All providers | G4: ← Pick a provider to filter every number and chart on this page. | T4: Dr. Patel, DPT
T5: Dr. Rivera, DPT
B6: Appointments scheduled | C6: No-show rate | D6: Late-cancel rate | E6: Completion rate | G6: Revenue lost to no-shows | H6: No-shows
B7: =COUNTIFS(Data!$F$2:$F$12113,IF($C$4="All providers","*",$C$4)) -> 12112 | C7: =COUNTIFS(Data!$F$2:$F$12113,IF($C$4="All providers","*",$C$4),Data!$L$2:$L$12113,"No-show")/MAX(1,COUNTIFS(Data!$F$2:$F$12113,IF($C$4="All providers","*",$C$4))) -> 0.12772457 | D7: =COUNTIFS(Data!$F$2:$F$12113,IF($C$4="All providers","*",$C$4),Data!$L$2:$L$12113,"Late cancel")/MAX(1,COUNTIFS(Data!$F$2:$F$12113,IF($C$4="All providers","*",$C$4))) -> 0.044005945 | E7: =COUNTIFS(Data!$F$2:$F$12113,IF($C$4="All providers","*",$C$4),Data!$L$2:$L$12113,"Completed")/MAX(1,COUNTIFS(Data!$F$2:$F$12113,IF($C$4="All providers","*",$C$4))) -> 0.77121863 | G7: =SUMIFS(Data!$R$2:$R$12113,Data!$F$2:$F$12113,IF($C$4="All providers","*",$C$4)) -> 184863.2 | H7: =COUNTIFS(Data!$F$2:$F$12113,IF($C$4="All providers","*",$C$4),Data!$L$2:$L$12113,"No-show") -> 1547
B9: What the data says
B10: • Reminders matter most: unreminded appointments no-show at 19% vs. 11% with a reminder. Closing the reminder gap is the fastest, cheapest fix.
B11: • Booking far out backfires: 26% no-show when booked 22+ days ahead vs. 10% within 2 days. Confirm long-lead appointments 48 hours out.
B12: • Mondays (14%) and Fridays (14%) are the weak days; Wednesdays are strongest (11%).
B13: • Medicaid (19%) and self-pay (16%) patients no-show most. Transportation and cost barriers are common drivers worth asking about at intake.
B14: • No-shows cost an estimated $184,863 in expected revenue this year. Cutting the rate by a quarter would recover about $46,216.
B15: Insights describe the full dataset (all providers). Tables and charts below follow the provider filter.
B17: By month
C18: Scheduled | D18: No-shows | E18: No-show rate
B19: 45931 | C19: =COUNTIFS(Data!$F$2:$F$12113,IF($C$4="All providers","*",$C$4),Data!$N$2:$N$12113,B19) -> 1051 | D19: =COUNTIFS(Data!$F$2:$F$12113,IF($C$4="All providers","*",$C$4),Data!$N$2:$N$12113,B19,Data!$L$2:$L$12113,"No-show") -> 125 | E19: =IFERROR(D19/C19,0) -> 0.11893435
B20: 45962 | C20: =COUNTIFS(Data!$F$2:$F$12113,IF($C$4="All providers","*",$C$4),Data!$N$2:$N$12113,B20) -> 858 | D20: =COUNTIFS(Data!$F$2:$F$12113,IF($C$4="All providers","*",$C$4),Data!$N$2:$N$12113,B20,Data!$L$2:$L$12113,"No-show") -> 134 | E20: =IFERROR(D20/C20,0) -> 0.15617716
B21: 45992 | C21: =COUNTIFS(Data!$F$2:$F$12113,IF($C$4="All providers","*",$C$4),Data!$N$2:$N$12113,B21) -> 1099 | D21: =COUNTIFS(Data!$F$2:$F$12113,IF($C$4="All providers","*",$C$4),Data!$N$2:$N$12113,B21,Data!$L$2:$L$12113,"No-show") -> 149 | E21: =IFERROR(D21/C21,0) -> 0.1355778
B22: 46023 | C22: =COUNTIFS(Data!$F$2:$F$12113,IF($C$4="All providers","*",$C$4),Data!$N$2:$N$12113,B22) -> 994 | D22: =COUNTIFS(Data!$F$2:$F$12113,IF($C$4="All providers","*",$C$4),Data!$N$2:$N$12113,B22,Data!$L$2:$L$12113,"No-show") -> 140 | E22: =IFERROR(D22/C22,0) -> 0.14084507
B23: 46054 | C23: =COUNTIFS(Data!$F$2:$F$12113,IF($C$4="All providers","*",$C$4),Data!$N$2:$N$12113,B23) -> 968 | D23: =COUNTIFS(Data!$F$2:$F$12113,IF($C$4="All providers","*",$C$4),Data!$N$2:$N$12113,B23,Data!$L$2:$L$12113,"No-show") -> 129 | E23: =IFERROR(D23/C23,0) -> 0.13326446
B24: 46082 | C24: =COUNTIFS(Data!$F$2:$F$12113,IF($C$4="All providers","*",$C$4),Data!$N$2:$N$12113,B24) -> 1116 | D24: =COUNTIFS(Data!$F$2:$F$12113,IF($C$4="All providers","*",$C$4),Data!$N$2:$N$12113,B24,Data!$L$2:$L$12113,"No-show") -> 150 | E24: =IFERROR(D24/C24,0) -> 0.1344086
B25: 46113 | C25: =COUNTIFS(Data!$F$2:$F$12113,IF($C$4="All providers","*",$C$4),Data!$N$2:$N$12113,B25) -> 1015 | D25: =COUNTIFS(Data!$F$2:$F$12113,IF($C$4="All providers","*",$C$4),Data!$N$2:$N$12113,B25,Data!$L$2:$L$12113,"No-show") -> 113 | E25: =IFERROR(D25/C25,0) -> 0.11133005
B26: 46143 | C26: =COUNTIFS(Data!$F$2:$F$12113,IF($C$4="All providers","*",$C$4),Data!$N$2:$N$12113,B26) -> 955 | D26: =COUNTIFS(Data!$F$2:$F$12113,IF($C$4="All providers","*",$C$4),Data!$N$2:$N$12113,B26,Data!$L$2:$L$12113,"No-show") -> 111 | E26: =IFERROR(D26/C26,0) -> 0.11623037
B27: 46174 | C27: =COUNTIFS(Data!$F$2:$F$12113,IF($C$4="All providers","*",$C$4),Data!$N$2:$N$12113,B27) -> 1025 | D27: =COUNTIFS(Data!$F$2:$F$12113,IF($C$4="All providers","*",$C$4),Data!$N$2:$N$12113,B27,Data!$L$2:$L$12113,"No-show") -> 123 | E27: =IFERROR(D27/C27,0) -> 0.12
B28: 46204 | C28: =COUNTIFS(Data!$F$2:$F$12113,IF($C$4="All providers","*",$C$4),Data!$N$2:$N$12113,B28) -> 1115 | D28: =COUNTIFS(Data!$F$2:$F$12113,IF($C$4="All providers","*",$C$4),Data!$N$2:$N$12113,B28,Data!$L$2:$L$12113,"No-show") -> 153 | E28: =IFERROR(D28/C28,0) -> 0.13721973
B29: 46235 | C29: =COUNTIFS(Data!$F$2:$F$12113,IF($C$4="All providers","*",$C$4),Data!$N$2:$N$12113,B29) -> 1075 | D29: =COUNTIFS(Data!$F$2:$F$12113,IF($C$4="All providers","*",$C$4),Data!$N$2:$N$12113,B29,Data!$L$2:$L$12113,"No-show") -> 140 | E29: =IFERROR(D29/C29,0) -> 0.13023256
B30: 46266 | C30: =COUNTIFS(Data!$F$2:$F$12113,IF($C$4="All providers","*",$C$4),Data!$N$2:$N$12113,B30) -> 841 | D30: =COUNTIFS(Data!$F$2:$F$12113,IF($C$4="All providers","*",$C$4),Data!$N$2:$N$12113,B30,Data!$L$2:$L$12113,"No-show") -> 80 | E30: =IFERROR(D30/C30,0) -> 0.095124851
B33: By day of week | G33: By booking lead time | L33: Reminder sent?
C34: Scheduled | D34: No-shows | E34: No-show rate | H34: Scheduled | I34: No-shows | J34: No-show rate | M34: Scheduled | N34: No-shows | O34: No-show rate
B35: Monday | C35: =COUNTIFS(Data!$F$2:$F$12113,IF($C$4="All providers","*",$C$4),Data!$C$2:$C$12113,B35) -> 2251 | D35: =COUNTIFS(Data!$F$2:$F$12113,IF($C$4="All providers","*",$C$4),Data!$C$2:$C$12113,B35,Data!$L$2:$L$12113,"No-show") -> 322 | E35: =IFERROR(D35/C35,0) -> 0.14304753 | G35: 0-2 days | H35: =COUNTIFS(Data!$F$2:$F$12113,IF($C$4="All providers","*",$C$4),Data!$O$2:$O$12113,G35) -> 1777 | I35: =COUNTIFS(Data!$F$2:$F$12113,IF($C$4="All providers","*",$C$4),Data!$O$2:$O$12113,G35,Data!$L$2:$L$12113,"No-show") -> 170 | J35: =IFERROR(I35/H35,0) -> 0.095666854 | L35: Yes | M35: =COUNTIFS(Data!$F$2:$F$12113,IF($C$4="All providers","*",$C$4),Data!$K$2:$K$12113,L35) -> 9443 | N35: =COUNTIFS(Data!$F$2:$F$12113,IF($C$4="All providers","*",$C$4),Data!$K$2:$K$12113,L35,Data!$L$2:$L$12113,"No-show") -> 1049 | O35: =IFERROR(N35/M35,0) -> 0.11108758
B36: Tuesday | C36: =COUNTIFS(Data!$F$2:$F$12113,IF($C$4="All providers","*",$C$4),Data!$C$2:$C$12113,B36) -> 2500 | D36: =COUNTIFS(Data!$F$2:$F$12113,IF($C$4="All providers","*",$C$4),Data!$C$2:$C$12113,B36,Data!$L$2:$L$12113,"No-show") -> 298 | E36: =IFERROR(D36/C36,0) -> 0.1192 | G36: 3-7 days | H36: =COUNTIFS(Data!$F$2:$F$12113,IF($C$4="All providers","*",$C$4),Data!$O$2:$O$12113,G36) -> 4997 | I36: =COUNTIFS(Data!$F$2:$F$12113,IF($C$4="All providers","*",$C$4),Data!$O$2:$O$12113,G36,Data!$L$2:$L$12113,"No-show") -> 529 | J36: =IFERROR(I36/H36,0) -> 0.10586352 | L36: No | M36: =COUNTIFS(Data!$F$2:$F$12113,IF($C$4="All providers","*",$C$4),Data!$K$2:$K$12113,L36) -> 2669 | N36: =COUNTIFS(Data!$F$2:$F$12113,IF($C$4="All providers","*",$C$4),Data!$K$2:$K$12113,L36,Data!$L$2:$L$12113,"No-show") -> 498 | O36: =IFERROR(N36/M36,0) -> 0.18658674
B37: Wednesday | C37: =COUNTIFS(Data!$F$2:$F$12113,IF($C$4="All providers","*",$C$4),Data!$C$2:$C$12113,B37) -> 2325 | D37: =COUNTIFS(Data!$F$2:$F$12113,IF($C$4="All providers","*",$C$4),Data!$C$2:$C$12113,B37,Data!$L$2:$L$12113,"No-show") -> 258 | E37: =IFERROR(D37/C37,0) -> 0.11096774 | G37: 8-14 days | H37: =COUNTIFS(Data!$F$2:$F$12113,IF($C$4="All providers","*",$C$4),Data!$O$2:$O$12113,G37) -> 3813 | I37: =COUNTIFS(Data!$F$2:$F$12113,IF($C$4="All providers","*",$C$4),Data!$O$2:$O$12113,G37,Data!$L$2:$L$12113,"No-show") -> 536 | J37: =IFERROR(I37/H37,0) -> 0.14057173
B38: Thursday | C38: =COUNTIFS(Data!$F$2:$F$12113,IF($C$4="All providers","*",$C$4),Data!$C$2:$C$12113,B38) -> 2151 | D38: =COUNTIFS(Data!$F$2:$F$12113,IF($C$4="All providers","*",$C$4),Data!$C$2:$C$12113,B38,Data!$L$2:$L$12113,"No-show") -> 253 | E38: =IFERROR(D38/C38,0) -> 0.11761971 | G38: 15-21 days | H38: =COUNTIFS(Data!$F$2:$F$12113,IF($C$4="All providers","*",$C$4),Data!$O$2:$O$12113,G38) -> 1326 | I38: =COUNTIFS(Data!$F$2:$F$12113,IF($C$4="All providers","*",$C$4),Data!$O$2:$O$12113,G38,Data!$L$2:$L$12113,"No-show") -> 261 | J38: =IFERROR(I38/H38,0) -> 0.19683258
B39: Friday | C39: =COUNTIFS(Data!$F$2:$F$12113,IF($C$4="All providers","*",$C$4),Data!$C$2:$C$12113,B39) -> 2885 | D39: =COUNTIFS(Data!$F$2:$F$12113,IF($C$4="All providers","*",$C$4),Data!$C$2:$C$12113,B39,Data!$L$2:$L$12113,"No-show") -> 416 | E39: =IFERROR(D39/C39,0) -> 0.14419411 | G39: 22+ days | H39: =COUNTIFS(Data!$F$2:$F$12113,IF($C$4="All providers","*",$C$4),Data!$O$2:$O$12113,G39) -> 199 | I39: =COUNTIFS(Data!$F$2:$F$12113,IF($C$4="All providers","*",$C$4),Data!$O$2:$O$12113,G39,Data!$L$2:$L$12113,"No-show") -> 51 | J39: =IFERROR(I39/H39,0) -> 0.25628141
B58: By payer | G58: By referral source | L58: By time of day
C59: Scheduled | D59: No-shows | E59: No-show rate | H59: Scheduled | I59: No-shows | J59: No-show rate | M59: Scheduled | N59: No-shows | O59: No-show rate
B60: Medicaid | C60: =COUNTIFS(Data!$F$2:$F$12113,IF($C$4="All providers","*",$C$4),Data!$H$2:$H$12113,B60) -> 1453 | D60: =COUNTIFS(Data!$F$2:$F$12113,IF($C$4="All providers","*",$C$4),Data!$H$2:$H$12113,B60,Data!$L$2:$L$12113,"No-show") -> 274 | E60: =IFERROR(D60/C60,0) -> 0.18857536 | G60: Orthopedic surgeon | H60: =COUNTIFS(Data!$F$2:$F$12113,IF($C$4="All providers","*",$C$4),Data!$I$2:$I$12113,G60) -> 3686 | I60: =COUNTIFS(Data!$F$2:$F$12113,IF($C$4="All providers","*",$C$4),Data!$I$2:$I$12113,G60,Data!$L$2:$L$12113,"No-show") -> 515 | J60: =IFERROR(I60/H60,0) -> 0.13971785 | L60: Early (7-10 AM) | M60: =COUNTIFS(Data!$F$2:$F$12113,IF($C$4="All providers","*",$C$4),Data!$P$2:$P$12113,L60) -> 3336 | N60: =COUNTIFS(Data!$F$2:$F$12113,IF($C$4="All providers","*",$C$4),Data!$P$2:$P$12113,L60,Data!$L$2:$L$12113,"No-show") -> 388 | O60: =IFERROR(N60/M60,0) -> 0.11630695
B61: Self-pay | C61: =COUNTIFS(Data!$F$2:$F$12113,IF($C$4="All providers","*",$C$4),Data!$H$2:$H$12113,B61) -> 743 | D61: =COUNTIFS(Data!$F$2:$F$12113,IF($C$4="All providers","*",$C$4),Data!$H$2:$H$12113,B61,Data!$L$2:$L$12113,"No-show") -> 118 | E61: =IFERROR(D61/C61,0) -> 0.15881561 | G61: Direct access (self) | H61: =COUNTIFS(Data!$F$2:$F$12113,IF($C$4="All providers","*",$C$4),Data!$I$2:$I$12113,G61) -> 1797 | I61: =COUNTIFS(Data!$F$2:$F$12113,IF($C$4="All providers","*",$C$4),Data!$I$2:$I$12113,G61,Data!$L$2:$L$12113,"No-show") -> 229 | J61: =IFERROR(I61/H61,0) -> 0.12743461 | L61: Midday (10 AM-2 PM) | M61: =COUNTIFS(Data!$F$2:$F$12113,IF($C$4="All providers","*",$C$4),Data!$P$2:$P$12113,L61) -> 4383 | N61: =COUNTIFS(Data!$F$2:$F$12113,IF($C$4="All providers","*",$C$4),Data!$P$2:$P$12113,L61,Data!$L$2:$L$12113,"No-show") -> 534 | O61: =IFERROR(N61/M61,0) -> 0.12183436
B62: Aetna | C62: =COUNTIFS(Data!$F$2:$F$12113,IF($C$4="All providers","*",$C$4),Data!$H$2:$H$12113,B62) -> 1317 | D62: =COUNTIFS(Data!$F$2:$F$12113,IF($C$4="All providers","*",$C$4),Data!$H$2:$H$12113,B62,Data!$L$2:$L$12113,"No-show") -> 181 | E62: =IFERROR(D62/C62,0) -> 0.13743356 | G62: Hospital discharge | H62: =COUNTIFS(Data!$F$2:$F$12113,IF($C$4="All providers","*",$C$4),Data!$I$2:$I$12113,G62) -> 837 | I62: =COUNTIFS(Data!$F$2:$F$12113,IF($C$4="All providers","*",$C$4),Data!$I$2:$I$12113,G62,Data!$L$2:$L$12113,"No-show") -> 104 | J62: =IFERROR(I62/H62,0) -> 0.12425329 | L62: Afternoon (2-4 PM) | M62: =COUNTIFS(Data!$F$2:$F$12113,IF($C$4="All providers","*",$C$4),Data!$P$2:$P$12113,L62) -> 2167 | N62: =COUNTIFS(Data!$F$2:$F$12113,IF($C$4="All providers","*",$C$4),Data!$P$2:$P$12113,L62,Data!$L$2:$L$12113,"No-show") -> 269 | O62: =IFERROR(N62/M62,0) -> 0.12413475
...

Sheet About
B1: ABOUT THIS PROJECT
B2: Portfolio sample by Krysten Jefferson · The Charted Co
B4: Purpose | C4: Show a small outpatient physical therapy practice where its missed appointments come from, what they cost, and which fixes would recover the most visits.
B5: Data | C5: 12,112 synthetic appointments for a fictional 4-therapist clinic, Oct 2025 to Sep 2026, generated in Python. No real patients, providers, or practices. Patterns (lead time, reminders, weekday, payer) are modeled on commonly reported no-show drivers.
B6: Privacy | C6: Built entirely on synthetic data. For a real practice, this dashboard runs inside the practice's own Microsoft 365 or Google Workspace on a de-identified scheduling export (no names, DOBs, or MRNs), so no PHI leaves the practice.
B7: How it works | C7: The Data tab holds one row per appointment with calculated helper columns (month, lead-time bucket, time of day, no-show flag, revenue lost). Every number on the Dashboard is a live COUNTIFS/SUMIFS formula, so pasting in a new month of data updates everything. The provider drop-down filters the whole page.
B8: Tools | C8: Python (pandas, NumPy) for data generation · Excel formulas, data validation, native charts
B9: Revenue note | C9: Expected revenue uses illustrative per-visit rates by payer (evaluations at 1.6x). Not real reimbursement data.
B11: Data dictionary
B12: appointment_id | C12: Unique appointment ID
B13: appointment_date | C13: Scheduled date
B14: weekday | C14: Day of week
B15: time_slot | C15: Scheduled start time
B16: patient_id | C16: Synthetic patient ID (not a real person)
B17: provider | C17: Treating therapist (fictional)
B18: visit_type | C18: Initial evaluation, follow-up, re-evaluation, or discharge
B19: payer | C19: Primary insurance
B20: referral_source | C20: How the patient was referred
B21: lead_time_days | C21: Days between booking and the appointment
B22: reminder_sent | C22: Whether a reminder text/call went out
B23: status | C23: Completed, No-show, Late cancel, or Cancelled
... B29: revenue_lost | C29: Calculated: expected revenue if no-show

Sheet Data
A1: appointment_id | B1: appointment_date | C1: weekday | D1: time_slot | E1: patient_id | F1: provider | G1: visit_type | H1: payer | I1: referral_source | J1: lead_time_days | K1: reminder_sent | L1: status | M1: expected_revenue | N1: month | O1: lead_time_bucket | P1: time_of_day | Q1: is_no_show | R1: revenue_lost
A2: A000933 | B2: 45931 | C2: Wednesday | D2: 07:00 | E2: PT-00464 | F2: Dr. Chen, DPT | G2: Discharge | H2: UnitedHealthcare | I2: Orthopedic surgeon | J2: 5 | K2: Yes | L2: Completed | M2: 115 | N2: =DATE(YEAR(B2),MONTH(B2),1) -> 45931 | O2: =IF(J2<=2,"0-2 days",IF(J2<=7,"3-7 days",IF(J2<=14,"8-14 days",IF(J2<=21,"15-21 days","22+ days")))) -> 3-7 days | P2: =IF(VALUE(LEFT(D2,2))<10,"Early (7-10 AM)",IF(VALUE(LEFT(D2,2))<14,"Midday (10 AM-2 PM)",IF(VALUE(LEFT(D2,2))<16,"Afternoon (2-4 PM)","Late (4-6 PM)"))) -> Early (7-10 AM) | Q2: =IF(L2="No-show",1,0) -> 0 | R2: =IF(L2="No-show",M2,0) -> 0
A3: A000934 | B3: 45931 | C3: Wednesday | D3: 07:00 | E3: PT-00966 | F3: Dr. Chen, DPT | G3: Follow-up visit | H3: Cigna | I3: Orthopedic surgeon | J3: 6 | K3: Yes | L3: Completed | M3: 116 | N3: =DATE(YEAR(B3),MONTH(B3),1) -> 45931 | O3: =IF(J3<=2,"0-2 days",IF(J3<=7,"3-7 days",IF(J3<=14,"8-14 days",IF(J3<=21,"15-21 days","22+ days")))) -> 3-7 days | P3: =IF(VALUE(LEFT(D3,2))<10,"Early (7-10 AM)",IF(VALUE(LEFT(D3,2))<14,"Midday (10 AM-2 PM)",IF(VALUE(LEFT(D3,2))<16,"Afternoon (2-4 PM)","Late (4-6 PM)"))) -> Early (7-10 AM) | Q3: =IF(L3="No-show",1,0) -> 0 | R3: =IF(L3="No-show",M3,0) -> 0
A4: A000935 | B4: 45931 | C4: Wednesday | D4: 07:30 | E4: PT-00185 | F4: Dr. Patel, DPT | G4: Re-evaluation | H4: BlueCross BlueShield | I4: Orthopedic surgeon | J4: 10 | K4: Yes | L4: Completed | M4: 192 | N4: =DATE(YEAR(B4),MONTH(B4),1) -> 45931 | O4: =IF(J4<=2,"0-2 days",IF(J4<=7,"3-7 days",IF(J4<=14,"8-14 days",IF(J4<=21,"15-21 days","22+ days")))) -> 8-14 days | P4: =IF(VALUE(LEFT(D4,2))<10,"Early (7-10 AM)",IF(VALUE(LEFT(D4,2))<14,"Midday (10 AM-2 PM)",IF(VALUE(LEFT(D4,2))<16,"Afternoon (2-4 PM)","Late (4-6 PM)"))) -> Early (7-10 AM) | Q4: =IF(L4="No-show",1,0) -> 0 | R4: =IF(L4="No-show",M4,0) -> 0
A5: A000936 | B5: 45931 | C5: Wednesday | D5: 07:30 | E5: PT-00461 | F5: Dr. Rivera, DPT | G5: Discharge | H5: Medicaid | I5: Website / Google | J5: 5 | K5: No | L5: Cancelled | M5: 72 | N5: =DATE(YEAR(B5),MONTH(B5),1) -> 45931 | O5: =IF(J5<=2,"0-2 days",IF(J5<=7,"3-7 days",IF(J5<=14,"8-14 days",IF(J5<=21,"15-21 days","22+ days")))) -> 3-7 days | P5: =IF(VALUE(LEFT(D5,2))<10,"Early (7-10 AM)",IF(VALUE(LEFT(D5,2))<14,"Midday (10 AM-2 PM)",IF(VALUE(LEFT(D5,2))<16,"Afternoon (2-4 PM)","Late (4-6 PM)"))) -> Early (7-10 AM) | Q5: =IF(L5="No-show",1,0) -> 0 | R5: =IF(L5="No-show",M5,0) -> 0
A6: A000937 | B6: 45931 | C6: Wednesday | D6: 07:30 | E6: PT-01149 | F6: Dr. Patel, DPT | G6: Discharge | H6: BlueCross BlueShield | I6: Primary care | J6: 4 | K6: Yes | L6: Completed | M6: 120 | N6: =DATE(YEAR(B6),MONTH(B6),1) -> 45931 | O6: =IF(J6<=2,"0-2 days",IF(J6<=7,"3-7 days",IF(J6<=14,"8-14 days",IF(J6<=21,"15-21 days","22+ days")))) -> 3-7 days | P6: =IF(VALUE(LEFT(D6,2))<10,"Early (7-10 AM)",IF(VALUE(LEFT(D6,2))<14,"Midday (10 AM-2 PM)",IF(VALUE(LEFT(D6,2))<16,"Afternoon (2-4 PM)","Late (4-6 PM)"))) -> Early (7-10 AM) | Q6: =IF(L6="No-show",1,0) -> 0 | R6: =IF(L6="No-show",M6,0) -> 0
A7: A000938 | B7: 45931 | C7: Wednesday | D7: 07:30 | E7: PT-01397 | F7: Dr. Patel, DPT | G7: Discharge | H7: Medicare | I7: Orthopedic surgeon | J7: 7 | K7: No | L7: Completed | M7: 105 | N7: =DATE(YEAR(B7),MONTH(B7),1) -> 45931 | O7: =IF(J7<=2,"0-2 days",IF(J7<=7,"3-7 days",IF(J7<=14,"8-14 days",IF(J7<=21,"15-21 days","22+ days")))) -> 3-7 days | P7: =IF(VALUE(LEFT(D7,2))<10,"Early (7-10 AM)",IF(VALUE(LEFT(D7,2))<14,"Midday (10 AM-2 PM)",IF(VALUE(LEFT(D7,2))<16,"Afternoon (2-4 PM)","Late (4-6 PM)"))) -> Early (7-10 AM) | Q7: =IF(L7="No-show",1,0) -> 0 | R7: =IF(L7="No-show",M7,0) -> 0
A8: A000939 | B8: 45931 | C8: Wednesday | D8: 08:00 | E8: PT-00907 | F8: Dr. Okafor, DPT | G8: Follow-up visit | H8: Medicare | I8: Primary care | J8: 6 | K8: Yes | L8: Completed | M8: 105 | N8: =DATE(YEAR(B8),MONTH(B8),1) -> 45931 | O8: =IF(J8<=2,"0-2 days",IF(J8<=7,"3-7 days",IF(J8<=14,"8-14 days",IF(J8<=21,"15-21 days","22+ days")))) -> 3-7 days | P8: =IF(VALUE(LEFT(D8,2))<10,"Early (7-10 AM)",IF(VALUE(LEFT(D8,2))<14,"Midday (10 AM-2 PM)",IF(VALUE(LEFT(D8,2))<16,"Afternoon (2-4 PM)","Late (4-6 PM)"))) -> Early (7-10 AM) | Q8: =IF(L8="No-show",1,0) -> 0 | R8: =IF(L8="No-show",M8,0) -> 0
A9: A000940 | B9: 45931 | C9: Wednesday | D9: 08:00 | E9: PT-01313 | F9: Dr. Chen, DPT | G9: Re-evaluation | H9: Aetna | I9: Orthopedic surgeon | J9: 7 | K9: No | L9: Completed | M9: 188.8 | N9: =DATE(YEAR(B9),MONTH(B9),1) -> 45931 | O9: =IF(J9<=2,"0-2 days",IF(J9<=7,"3-7 days",IF(J9<=14,"8-14 days",IF(J9<=21,"15-21 days","22+ days")))) -> 3-7 days | P9: =IF(VALUE(LEFT(D9,2))<10,"Early (7-10 AM)",IF(VALUE(LEFT(D9,2))<14,"Midday (10 AM-2 PM)",IF(VALUE(LEFT(D9,2))<16,"Afternoon (2-4 PM)","Late (4-6 PM)"))) -> Early (7-10 AM) | Q9: =IF(L9="No-show",1,0) -> 0 | R9: =IF(L9="No-show",M9,0) -> 0
A10: A000941 | B10: 45931 | C10: Wednesday | D10: 08:00 | E10: PT-01381 | F10: Dr. Rivera, DPT | G10: Follow-up visit | H10: BlueCross BlueShield | I10: Orthopedic surgeon | J10: 6 | K10: Yes | L10: Completed | M10: 120 | N10: =DATE(YEAR(B10),MONTH(B10),1) -> 45931 | O10: =IF(J10<=2,"0-2 days",IF(J10<=7,"3-7 days",IF(J10<=14,"8-14 days",IF(J10<=21,"15-21 days","22+ days")))) -> 3-7 days | P10: =IF(VALUE(LEFT(D10,2))<10,"Early (7-10 AM)",IF(VALUE(LEFT(D10,2))<14,"Midday (10 AM-2 PM)",IF(VALUE(LEFT(D10,2))<16,"Afternoon (2-4 PM)","Late (4-6 PM)"))) -> Early (7-10 AM) | Q10: =IF(L10="No-show",1,0) -> 0 | R10: =IF(L10="No-show",M10,0) -> 0
A11: A000942 | B11: 45931 | C11: Wednesday | D11: 09:00 | E11: PT-00399 | F11: Dr. Okafor, DPT | G11: Follow-up visit | H11: Aetna | I11: Sports medicine | J11: 8 | K11: No | L11: Completed | M11: 118 | N11: =DATE(YEAR(B11),MONTH(B11),1) -> 45931 | O11: =IF(J11<=2,"0-2 days",IF(J11<=7,"3-7 days",IF(J11<=14,"8-14 days",IF(J11<=21,"15-21 days","22+ days")))) -> 8-14 days | P11: =IF(VALUE(LEFT(D11,2))<10,"Early (7-10 AM)",IF(VALUE(LEFT(D11,2))<14,"Midday (10 AM-2 PM)",IF(VALUE(LEFT(D11,2))<16,"Afternoon (2-4 PM)","Late (4-6 PM)"))) -> Early (7-10 AM) | Q11: =IF(L11="No-show",1,0) -> 0 | R11: =IF(L11="No-show",M11,0) -> 0
A12: A000943 | B12: 45931 | C12: Wednesday | D12: 09:00 | E12: PT-00560 | F12: Dr. Chen, DPT | G12: Re-evaluation | H12: UnitedHealthcare | I12: Website / Google | J12: 24 | K12: Yes | L12: Completed | M12: 184 | N12: =DATE(YEAR(B12),MONTH(B12),1) -> 45931 | O12: =IF(J12<=2,"0-2 days",IF(J12<=7,"3-7 days",IF(J12<=14,"8-14 days",IF(J12<=21,"15-21 days","22+ days")))) -> 22+ days | P12: =IF(VALUE(LEFT(D12,2))<10,"Early (7-10 AM)",IF(VALUE(LEFT(D12,2))<14,"Midday (10 AM-2 PM)",IF(VALUE(LEFT(D12,2))<16,"Afternoon (2-4 PM)","Late (4-6 PM)"))) -> Early (7-10 AM) | Q12: =IF(L12="No-show",1,0) -> 0 | R12: =IF(L12="No-show",M12,0) -> 0
A13: A000944 | B13: 45931 | C13: Wednesday | D13: 09:00 | E13: PT-01150 | F13: Dr. Okafor, DPT | G13: Follow-up visit | H13: Cigna | I13: Sports medicine | J13: 2 | K13: Yes | L13: Completed | M13: 116 | N13: =DATE(YEAR(B13),MONTH(B13),1) -> 45931 | O13: =IF(J13<=2,"0-2 days",IF(J13<=7,"3-7 days",IF(J13<=14,"8-14 days",IF(J13<=21,"15-21 days","22+ days")))) -> 0-2 days | P13: =IF(VALUE(LEFT(D13,2))<10,"Early (7-10 AM)",IF(VALUE(LEFT(D13,2))<14,"Midday (10 AM-2 PM)",IF(VALUE(LEFT(D13,2))<16,"Afternoon (2-4 PM)","Late (4-6 PM)"))) -> Early (7-10 AM) | Q13: =IF(L13="No-show",1,0) -> 0 | R13: =IF(L13="No-show",M13,0) -> 0
... A12113: A013044 | B12113: 46295 | C12113: Wednesday | D12113: 16:30 | E12113: PT-01231 | F12113: Dr. Okafor, DPT | G12113: Follow-up visit | H12113: UnitedHealthcare | I12113: Orthopedic surgeon | J12113: 8 | K12113: No | L12113: Completed | M12113: 115 | N12113: =DATE(YEAR(B12113),MONTH(B12113),1) -> 46266 | O12113: =IF(J12113<=2,"0-2 days",IF(J12113<=7,"3-7 days",IF(J12113<=14,"8-14 days",IF(J12113<=21,"15-21 days","22+ days")))) -> 8-14 days | P12113: =IF(VALUE(LEFT(D12113,2))<10,"Early (7-10 AM)",IF(VALUE(LEFT(D12113,2))<14,"Midday (10 AM-2 PM)",IF(VALUE(LEFT(D12113,2))<16,"Afternoon (2-4 PM)","Late (4-6 PM)"))) -> Late (4-6 PM) | Q12113: =IF(L12113="No-show",1,0) -> 0 | R12113: =IF(L12113="No-show",M12113,0) -> 0
